From 9eb914d6e4305ae3c727f6d5136109b714518c8f Mon Sep 17 00:00:00 2001
From: Masatake Iwasaki <iwasakims@apache.org>
Date: Fri, 6 May 2016 15:36:47 +0900
Subject: [PATCH 1510/2748] HDFS-2043. TestHFlush failing intermittently.
 Contributed by Lin Yiqun.

(cherry picked from commit 2835f146b551f911ea13307e7762759813898757)

Change-Id: I5d8b2516fb6ee711bf2dafcfca066344835d05cb
---
 .../java/org/apache/hadoop/hdfs/TestHFlush.java    |   10 ++++++++--
 1 file changed, 8 insertions(+), 2 deletions(-)

diff --git a/hadoop-hdfs-project/hadoop-hdfs/src/test/java/org/apache/hadoop/hdfs/TestHFlush.java b/hadoop-hdfs-project/hadoop-hdfs/src/test/java/org/apache/hadoop/hdfs/TestHFlush.java
index 9ada95f..3606e81 100644
--- a/hadoop-hdfs-project/hadoop-hdfs/src/test/java/org/apache/hadoop/hdfs/TestHFlush.java
+++ b/hadoop-hdfs-project/hadoop-hdfs/src/test/java/org/apache/hadoop/hdfs/TestHFlush.java
@@ -368,8 +368,14 @@ public void testHFlushInterrupted() throws Exception {
         // If we got the exception, we shouldn't have interrupted status anymore.
         assertFalse(Thread.interrupted());
 
-        // Now do a successful close.
-        stm.close();
+        // Do the try-catch in the second stm.close() avoid that streamer was already
+        // closed in other places.
+        try {
+          // Now do a successful close.
+          stm.close();
+        } catch (IOException e) {
+          System.out.println("Got expected exception during second close");
+        }
       }
 
 
-- 
1.7.9.5

